2023-03-21 13:32:50 [ERROR] util.logger generate_token_api.py:47: Failed : Invalid OTP
Traceback (most recent call last):
  File "C:\aravind\lens35\apps\employees\apis\authenticate\generate_token_api.py", line 21, in index
    otp = validate_and_format_otp(data.get("otp", None))
          ^^^^^^^^^^^^^^^^^^^^^^^^^^^^^^^^^^^^^^^^^^^^^^
  File "C:\aravind\lens35\util\regex.py", line 23, in validate_and_format_otp
    raise Exception("Invalid OTP")
Exception: Invalid OTP

2023-03-21 13:33:27 [ERROR] util.logger basic_info.py:71: Failed to update employee basic info : 554ab970-d1b7-46e2-8b72-f102463eb97f - Profile name is already used
Traceback (most recent call last):
  File "C:\aravind\lens35\apps\employees\apis\profile\update\basic_info.py", line 32, in index
    raise Exception("Profile name is already used")
Exception: Profile name is already used

2023-03-21 13:33:35 [ERROR] util.logger basic_info.py:71: Failed to update employee basic info : 554ab970-d1b7-46e2-8b72-f102463eb97f - This Email ID is already used
Traceback (most recent call last):
  File "C:\aravind\lens35\apps\employees\apis\profile\update\basic_info.py", line 45, in index
    raise Exception("This Email ID is already used")
Exception: This Email ID is already used

2023-03-21 13:33:45 [ERROR] util.logger basic_info.py:71: Failed to update employee basic info : 554ab970-d1b7-46e2-8b72-f102463eb97f - "to" argument must be a list or tuple
Traceback (most recent call last):
  File "C:\aravind\lens35\apps\employees\apis\profile\update\basic_info.py", line 47, in index
    send_email("email_verification_template", {"employee_id":employee_id}, email_id)
  File "C:\aravind\lens35\util\email_util.py", line 20, in send_email
    msg = EmailMultiAlternatives(subject, text_message, from_email, recipient_list)
          ^^^^^^^^^^^^^^^^^^^^^^^^^^^^^^^^^^^^^^^^^^^^^^^^^^^^^^^^^^^^^^^^^^^^^^^^^
  File "C:\Users\apillai\AppData\Local\Programs\Python\Python311\Lib\site-packages\django\core\mail\message.py", line 459, in __init__
    super().__init__(
  File "C:\Users\apillai\AppData\Local\Programs\Python\Python311\Lib\site-packages\django\core\mail\message.py", line 216, in __init__
    raise TypeError('"to" argument must be a list or tuple')
TypeError: "to" argument must be a list or tuple

2023-03-21 13:38:18 [ERROR] util.logger generate_token_api.py:47: Failed : Invalid OTP
Traceback (most recent call last):
  File "C:\aravind\lens35\apps\employees\apis\authenticate\generate_token_api.py", line 21, in index
    otp = validate_and_format_otp(data.get("otp", None))
          ^^^^^^^^^^^^^^^^^^^^^^^^^^^^^^^^^^^^^^^^^^^^^^
  File "C:\aravind\lens35\util\regex.py", line 23, in validate_and_format_otp
    raise Exception("Invalid OTP")
Exception: Invalid OTP

2023-03-21 13:38:23 [ERROR] util.logger generate_token_api.py:47: Failed : Invalid OTP
Traceback (most recent call last):
  File "C:\aravind\lens35\apps\employees\apis\authenticate\generate_token_api.py", line 21, in index
    otp = validate_and_format_otp(data.get("otp", None))
          ^^^^^^^^^^^^^^^^^^^^^^^^^^^^^^^^^^^^^^^^^^^^^^
  File "C:\aravind\lens35\util\regex.py", line 23, in validate_and_format_otp
    raise Exception("Invalid OTP")
Exception: Invalid OTP

2023-03-21 13:38:39 [ERROR] util.logger generate_token_api.py:47: Failed : Invalid OTP
Traceback (most recent call last):
  File "C:\aravind\lens35\apps\employees\apis\authenticate\generate_token_api.py", line 21, in index
    otp = validate_and_format_otp(data.get("otp", None))
          ^^^^^^^^^^^^^^^^^^^^^^^^^^^^^^^^^^^^^^^^^^^^^^
  File "C:\aravind\lens35\util\regex.py", line 23, in validate_and_format_otp
    raise Exception("Invalid OTP")
Exception: Invalid OTP

2023-03-21 13:42:38 [ERROR] util.logger generate_token_api.py:47: Failed : Invalid OTP
Traceback (most recent call last):
  File "C:\aravind\lens35\apps\customers\apis\authenticate\generate_token_api.py", line 21, in index
    otp = validate_and_format_otp(data.get("otp", None))
          ^^^^^^^^^^^^^^^^^^^^^^^^^^^^^^^^^^^^^^^^^^^^^^
  File "C:\aravind\lens35\util\regex.py", line 23, in validate_and_format_otp
    raise Exception("Invalid OTP")
Exception: Invalid OTP

2023-03-21 13:44:03 [ERROR] util.logger handle_booking.py:190: Failed to handle the booking request None
Traceback (most recent call last):
  File "C:\aravind\lens35\apps\bookings\apis\customers\handle_booking.py", line 74, in index
    raise Exception("Event date must be on or after today")
Exception: Event date must be on or after today

2023-03-21 13:44:51 [ERROR] util.logger handle_booking.py:190: Failed to handle the booking request None
Traceback (most recent call last):
  File "C:\aravind\lens35\apps\bookings\apis\customers\handle_booking.py", line 155, in index
    address = "{}, {}".format(booking.event_city, booking.pincode)
                                                  ^^^^^^^^^^^^^^^
AttributeError: 'Bookings' object has no attribute 'pincode'

2023-03-21 13:45:13 [ERROR] util.logger handle_booking.py:190: Failed to handle the booking request None
Traceback (most recent call last):
  File "C:\Users\apillai\AppData\Local\Programs\Python\Python311\Lib\site-packages\django\db\backends\utils.py", line 89, in _execute
    return self.cursor.execute(sql, params)
           ^^^^^^^^^^^^^^^^^^^^^^^^^^^^^^^^
psycopg2.errors.UndefinedColumn: column "event_latitude" of relation "bookings" does not exist
LINE 1: ...vent_postal_code", "event_city", "event_address", "event_lat...
                                                             ^


The above exception was the direct cause of the following exception:

Traceback (most recent call last):
  File "C:\aravind\lens35\apps\bookings\apis\customers\handle_booking.py", line 175, in index
    booking.save()
  File "C:\Users\apillai\AppData\Local\Programs\Python\Python311\Lib\site-packages\django\db\models\base.py", line 812, in save
    self.save_base(
  File "C:\Users\apillai\AppData\Local\Programs\Python\Python311\Lib\site-packages\django\db\models\base.py", line 863, in save_base
    updated = self._save_table(
              ^^^^^^^^^^^^^^^^^
  File "C:\Users\apillai\AppData\Local\Programs\Python\Python311\Lib\site-packages\django\db\models\base.py", line 1006, in _save_table
    results = self._do_insert(
              ^^^^^^^^^^^^^^^^
  File "C:\Users\apillai\AppData\Local\Programs\Python\Python311\Lib\site-packages\django\db\models\base.py", line 1047, in _do_insert
    return manager._insert(
           ^^^^^^^^^^^^^^^^
  File "C:\Users\apillai\AppData\Local\Programs\Python\Python311\Lib\site-packages\django\db\models\manager.py", line 85, in manager_method
    return getattr(self.get_queryset(), name)(*args, **kwargs)
           ^^^^^^^^^^^^^^^^^^^^^^^^^^^^^^^^^^^^^^^^^^^^^^^^^^^
  File "C:\Users\apillai\AppData\Local\Programs\Python\Python311\Lib\site-packages\django\db\models\query.py", line 1791, in _insert
    return query.get_compiler(using=using).execute_sql(returning_fields)
           ^^^^^^^^^^^^^^^^^^^^^^^^^^^^^^^^^^^^^^^^^^^^^^^^^^^^^^^^^^^^^
  File "C:\Users\apillai\AppData\Local\Programs\Python\Python311\Lib\site-packages\django\db\models\sql\compiler.py", line 1660, in execute_sql
    cursor.execute(sql, params)
  File "C:\Users\apillai\AppData\Local\Programs\Python\Python311\Lib\site-packages\django\db\backends\utils.py", line 67, in execute
    return self._execute_with_wrappers(
           ^^^^^^^^^^^^^^^^^^^^^^^^^^^^
  File "C:\Users\apillai\AppData\Local\Programs\Python\Python311\Lib\site-packages\django\db\backends\utils.py", line 80, in _execute_with_wrappers
    return executor(sql, params, many, context)
           ^^^^^^^^^^^^^^^^^^^^^^^^^^^^^^^^^^^^
  File "C:\Users\apillai\AppData\Local\Programs\Python\Python311\Lib\site-packages\django\db\backends\utils.py", line 84, in _execute
    with self.db.wrap_database_errors:
  File "C:\Users\apillai\AppData\Local\Programs\Python\Python311\Lib\site-packages\django\db\utils.py", line 91, in __exit__
    raise dj_exc_value.with_traceback(traceback) from exc_value
  File "C:\Users\apillai\AppData\Local\Programs\Python\Python311\Lib\site-packages\django\db\backends\utils.py", line 89, in _execute
    return self.cursor.execute(sql, params)
           ^^^^^^^^^^^^^^^^^^^^^^^^^^^^^^^^
django.db.utils.ProgrammingError: column "event_latitude" of relation "bookings" does not exist
LINE 1: ...vent_postal_code", "event_city", "event_address", "event_lat...
                                                             ^


2023-03-21 13:52:52 [ERROR] util.logger handle_booking.py:190: Failed to handle the booking request None
Traceback (most recent call last):
  File "C:\aravind\lens35\apps\bookings\apis\customers\handle_booking.py", line 104, in index
    raise Exception("Minimum Booking must be for 2 Hours")
Exception: Minimum Booking must be for 2 Hours

2023-03-21 14:08:05 [ERROR] util.logger list_bookings.py:67: Failed to fetch the bookings for employee 976b4889-4fd6-4ccc-a7ce-f540a5e89f48
Traceback (most recent call last):
  File "C:\aravind\lens35\apps\bookings\apis\employees\list_bookings.py", line 19, in index
    event_date = timezone.now().date() if (event_date == None or event_date == "") else datetime.fromisoformat(event_date).date()
                                                                                        ^^^^^^^^^^^^^^^^^^^^^^^^^^^^^^^^^^
ValueError: Invalid isoformat string: '23-03-2023'

2023-03-21 14:16:13 [ERROR] util.logger list_bookings.py:73: Failed to fetch the bookings for employee 976b4889-4fd6-4ccc-a7ce-f540a5e89f48
Traceback (most recent call last):
  File "C:\aravind\lens35\apps\bookings\apis\employees\list_bookings.py", line 68, in index
    "services": list(booking.services.values_list('service', flat=True).distinct())
                     ^^^^^^^^^^^^^^^^
AttributeError: 'Bookings' object has no attribute 'services'

2023-03-21 14:22:50 [ERROR] util.logger list_bookings.py:73: Failed to fetch the bookings for employee 976b4889-4fd6-4ccc-a7ce-f540a5e89f48
Traceback (most recent call last):
  File "C:\aravind\lens35\apps\bookings\apis\employees\list_bookings.py", line 68, in index
    "services": list(booking.services.values_list('service', flat=True).distinct())
                     ^^^^^^^^^^^^^^^^
AttributeError: 'Bookings' object has no attribute 'services'

2023-03-21 14:28:31 [ERROR] util.logger list_bookings.py:75: Failed to fetch the bookings for employee 976b4889-4fd6-4ccc-a7ce-f540a5e89f48
Traceback (most recent call last):
  File "C:\Users\apillai\AppData\Local\Programs\Python\Python311\Lib\site-packages\django\db\models\sql\query.py", line 2142, in add_fields
    join_info = self.setup_joins(
                ^^^^^^^^^^^^^^^^^
  File "C:\Users\apillai\AppData\Local\Programs\Python\Python311\Lib\site-packages\django\db\models\sql\query.py", line 1808, in setup_joins
    path, final_field, targets, rest = self.names_to_path(
                                       ^^^^^^^^^^^^^^^^^^^
  File "C:\Users\apillai\AppData\Local\Programs\Python\Python311\Lib\site-packages\django\db\models\sql\query.py", line 1709, in names_to_path
    raise FieldError(
django.core.exceptions.FieldError: Cannot resolve keyword 'service_code' into field. Choices are: booking, booking_id, created_time, employee, employee_id, employeepreference, id, lifecycle, retired, service, service_id

During handling of the above exception, another exception occurred:

Traceback (most recent call last):
  File "C:\aravind\lens35\apps\bookings\apis\employees\list_bookings.py", line 63, in index
    services = Services.objects.filter(booking = booking, employee = None).values_list('service_code', flat=True).distinct()
               ^^^^^^^^^^^^^^^^^^^^^^^^^^^^^^^^^^^^^^^^^^^^^^^^^^^^^^^^^^^^^^^^^^^^^^^^^^^^^^^^^^^^^^^^^^^^^^^^^^
  File "C:\Users\apillai\AppData\Local\Programs\Python\Python311\Lib\site-packages\django\db\models\query.py", line 1330, in values_list
    clone = self._values(*_fields, **expressions)
            ^^^^^^^^^^^^^^^^^^^^^^^^^^^^^^^^^^^^^
  File "C:\Users\apillai\AppData\Local\Programs\Python\Python311\Lib\site-packages\django\db\models\query.py", line 1293, in _values
    clone.query.set_values(fields)
  File "C:\Users\apillai\AppData\Local\Programs\Python\Python311\Lib\site-packages\django\db\models\sql\query.py", line 2437, in set_values
    self.add_fields(field_names, True)
  File "C:\Users\apillai\AppData\Local\Programs\Python\Python311\Lib\site-packages\django\db\models\sql\query.py", line 2175, in add_fields
    raise FieldError(
django.core.exceptions.FieldError: Cannot resolve keyword 'service_code' into field. Choices are: booking, booking_id, created_time, employee, employee_id, employeepreference, id, lifecycle, retired, service, service_id

2023-03-21 16:30:54 [ERROR] django.request log.py:241: Internal Server Error: /bookings/apis/employees/bookings/accept/
Traceback (most recent call last):
  File "C:\Users\apillai\AppData\Local\Programs\Python\Python311\Lib\site-packages\django\core\handlers\exception.py", line 55, in inner
    response = get_response(request)
               ^^^^^^^^^^^^^^^^^^^^^
  File "C:\Users\apillai\AppData\Local\Programs\Python\Python311\Lib\site-packages\django\core\handlers\base.py", line 197, in _get_response
    response = wrapped_callback(request, *callback_args, **callback_kwargs)
               ^^^^^^^^^^^^^^^^^^^^^^^^^^^^^^^^^^^^^^^^^^^^^^^^^^^^^^^^^^^^
  File "C:\Users\apillai\AppData\Local\Programs\Python\Python311\Lib\site-packages\django\views\decorators\csrf.py", line 54, in wrapped_view
    return view_func(*args, **kwargs)
           ^^^^^^^^^^^^^^^^^^^^^^^^^^
  File "C:\Users\apillai\AppData\Local\Programs\Python\Python311\Lib\site-packages\django\views\generic\base.py", line 103, in view
    return self.dispatch(request, *args, **kwargs)
           ^^^^^^^^^^^^^^^^^^^^^^^^^^^^^^^^^^^^^^^
  File "C:\Users\apillai\AppData\Local\Programs\Python\Python311\Lib\site-packages\rest_framework\views.py", line 509, in dispatch
    response = self.handle_exception(exc)
               ^^^^^^^^^^^^^^^^^^^^^^^^^^
  File "C:\Users\apillai\AppData\Local\Programs\Python\Python311\Lib\site-packages\rest_framework\views.py", line 469, in handle_exception
    self.raise_uncaught_exception(exc)
  File "C:\Users\apillai\AppData\Local\Programs\Python\Python311\Lib\site-packages\rest_framework\views.py", line 480, in raise_uncaught_exception
    raise exc
  File "C:\Users\apillai\AppData\Local\Programs\Python\Python311\Lib\site-packages\rest_framework\views.py", line 506, in dispatch
    response = handler(request, *args, **kwargs)
               ^^^^^^^^^^^^^^^^^^^^^^^^^^^^^^^^^
  File "C:\Users\apillai\AppData\Local\Programs\Python\Python311\Lib\site-packages\rest_framework\decorators.py", line 50, in handler
    return func(*args, **kwargs)
           ^^^^^^^^^^^^^^^^^^^^^
TypeError: index() missing 1 required positional argument: 'booking_id'
2023-03-21 16:31:17 [ERROR] django.request log.py:241: Internal Server Error: /bookings/apis/employees/bookings/accept/
Traceback (most recent call last):
  File "C:\Users\apillai\AppData\Local\Programs\Python\Python311\Lib\site-packages\django\core\handlers\exception.py", line 55, in inner
    response = get_response(request)
               ^^^^^^^^^^^^^^^^^^^^^
  File "C:\Users\apillai\AppData\Local\Programs\Python\Python311\Lib\site-packages\django\core\handlers\base.py", line 197, in _get_response
    response = wrapped_callback(request, *callback_args, **callback_kwargs)
               ^^^^^^^^^^^^^^^^^^^^^^^^^^^^^^^^^^^^^^^^^^^^^^^^^^^^^^^^^^^^
  File "C:\Users\apillai\AppData\Local\Programs\Python\Python311\Lib\site-packages\django\views\decorators\csrf.py", line 54, in wrapped_view
    return view_func(*args, **kwargs)
           ^^^^^^^^^^^^^^^^^^^^^^^^^^
  File "C:\Users\apillai\AppData\Local\Programs\Python\Python311\Lib\site-packages\django\views\generic\base.py", line 103, in view
    return self.dispatch(request, *args, **kwargs)
           ^^^^^^^^^^^^^^^^^^^^^^^^^^^^^^^^^^^^^^^
  File "C:\Users\apillai\AppData\Local\Programs\Python\Python311\Lib\site-packages\rest_framework\views.py", line 509, in dispatch
    response = self.handle_exception(exc)
               ^^^^^^^^^^^^^^^^^^^^^^^^^^
  File "C:\Users\apillai\AppData\Local\Programs\Python\Python311\Lib\site-packages\rest_framework\views.py", line 469, in handle_exception
    self.raise_uncaught_exception(exc)
  File "C:\Users\apillai\AppData\Local\Programs\Python\Python311\Lib\site-packages\rest_framework\views.py", line 480, in raise_uncaught_exception
    raise exc
  File "C:\Users\apillai\AppData\Local\Programs\Python\Python311\Lib\site-packages\rest_framework\views.py", line 506, in dispatch
    response = handler(request, *args, **kwargs)
               ^^^^^^^^^^^^^^^^^^^^^^^^^^^^^^^^^
  File "C:\Users\apillai\AppData\Local\Programs\Python\Python311\Lib\site-packages\rest_framework\decorators.py", line 50, in handler
    return func(*args, **kwargs)
           ^^^^^^^^^^^^^^^^^^^^^
TypeError: index() missing 1 required positional argument: 'booking_id'
2023-03-21 16:38:04 [ERROR] util.logger accept_booking.py:37: Failed to fetch the bookings for employee 976b4889-4fd6-4ccc-a7ce-f540a5e89f48
Traceback (most recent call last):
  File "C:\aravind\lens35\apps\bookings\apis\employees\accept_booking.py", line 33, in index
    raise Exception("Employee is not registered to accept {} bookings".format(service.service))
Exception: Employee is not registered to accept photography bookings

2023-03-21 16:42:22 [ERROR] util.logger accept_booking.py:44: Failed to fetch the bookings for employee 976b4889-4fd6-4ccc-a7ce-f540a5e89f48
Traceback (most recent call last):
  File "C:\aravind\lens35\apps\bookings\apis\employees\accept_booking.py", line 26, in index
    raise Exception("Invalid service id found in the request")
Exception: Invalid service id found in the request

2023-03-21 16:51:54 [ERROR] util.logger remove_booking.py:35: Failed to remove booking/service for employee 976b4889-4fd6-4ccc-a7ce-f540a5e89f48
Traceback (most recent call last):
  File "C:\aravind\lens35\apps\bookings\apis\employees\remove_booking.py", line 21, in index
    service_id_list.append(UUID(sid))
                           ^^^^^^^^^
  File "C:\Users\apillai\AppData\Local\Programs\Python\Python311\Lib\uuid.py", line 179, in __init__
    int = int_(hex, 16)
          ^^^^^^^^^^^^^
ValueError: invalid literal for int() with base 16: '90834251bd8c4451ab9c0018107cadcs'

2023-03-21 16:52:08 [ERROR] util.logger remove_booking.py:35: Failed to remove booking/service for employee 976b4889-4fd6-4ccc-a7ce-f540a5e89f48
Traceback (most recent call last):
  File "C:\aravind\lens35\apps\bookings\apis\employees\remove_booking.py", line 25, in index
    raise Exception("Invalid service id found in the request")
Exception: Invalid service id found in the request

